<?xml version='1.0'?>
<sdf version='1.5'>
      <model name = 'submarine'>
            <pose>0 0 1.5 1.5707963267948966 0 0</pose>
            <link name = 'body'>
                  <!--
                        Main body housing. pose offset from ocs origin slightly
                  -->
                  <!-- <pose> 0 0 -0.5 0 0 0 </pose> -->
                  <inertial>
                        <!-- this definitely needs to be messed with -->
                        <mass>50.0</mass>
                        <inertia>
                              <!-- From http://gazebosim.org/tutorials?tut=inertia&cat -->
                              <ixx>0.083</ixx>       <!-- for a box: ixx = 0.083 * mass * (y*y + z*z) -->
                              <ixy>0.0</ixy>         <!-- for a box: ixy = 0 -->
                              <ixz>0.0</ixz>         <!-- for a box: ixz = 0 -->
                              <iyy>0.083</iyy>       <!-- for a box: iyy = 0.083 * mass * (x*x + z*z) -->
                              <iyz>0.0</iyz>         <!-- for a box: iyz = 0 -->
                              <izz>0.083</izz>       <!-- for a box: izz = 0.083 * mass * (x*x + y*y) -->
                        </inertia>
                  </inertial>

                  <visual name = 'body_visual'>
                        <geometry>
                              <cylinder>
                                    <radius>0.15</radius>
                                    <length>1.0</length>
                              </cylinder>
                        </geometry>
                  </visual>

                  <collision name='body_collision'>
                        <geometry>
                              <cylinder>
                                    <radius>0.15</radius>
                                    <length>1.0</length>
                              </cylinder>
                        </geometry>
                  </collision>
            </link>

            <link name = 'keel'>
                  <pose relative_to = 'body'> 0 -0.15 0.1 0 0 0 </pose> -->
                  <inertial>
                        <!-- this definitely needs to be messed with -->
                        <mass>100.0</mass>
                        <inertia>
                              <!-- From http://gazebosim.org/tutorials?tut=inertia&cat -->
                              <ixx>0.083</ixx>       <!-- for a box: ixx = 0.083 * mass * (y*y + z*z) -->
                              <ixy>0.0</ixy>         <!-- for a box: ixy = 0 -->
                              <ixz>0.0</ixz>         <!-- for a box: ixz = 0 -->
                              <iyy>0.083</iyy>       <!-- for a box: iyy = 0.083 * mass * (x*x + z*z) -->
                              <iyz>0.0</iyz>         <!-- for a box: iyz = 0 -->
                              <izz>0.083</izz>       <!-- for a box: izz = 0.083 * mass * (x*x + y*y) -->
                        </inertia>
                  </inertial>

                  <visual name = 'keel_visual'>
                        <geometry>
                              <box>
                                    <size>.1 .1 .5</size>
                              </box>
                        </geometry>
                  </visual>

                  <collision name='keel_collision'>
                        <geometry>
                              <box>
                                    <size>.1 .1 .5</size>
                              </box>
                        </geometry>
                  </collision>
            </link>


            <link name = 'left_thrust'>
                  <!-- left thruster housing and mount block -->
                  <pose> -0.3 0 0.3 0 0 0 </pose>
                  <inertial>
                        <mass>13.0</mass>
                        <!-- same source as body inertias -->
                        <inertia>
                              <ixx>0.083</ixx>
                              <ixy>0.0</ixy>
                              <ixz>0.0</ixz>
                              <iyy>0.083</iyy>
                              <iyz>0.0</iyz>
                              <izz>0.083</izz>
                        </inertia>
                  </inertial>

                  <visual name = 'left_housing_visual'>
                        <geometry>
                              <cylinder>
                                    <radius>0.05</radius>
                                    <length>0.3</length>
                              </cylinder>
                        </geometry>
                        <!--<pose> 0.15 0 0 0 0 0 </pose>-->
                  </visual>

                  <collision name='left_housing_collision'>
                        <geometry>
                              <cylinder>
                                    <radius>0.05</radius>
                                    <length>0.3</length>
                              </cylinder>
                        </geometry>
                  </collision>

                  <visual name = 'left_mount_visual'>
                        <pose> 0.1 0 0 0 0 0 </pose>
                        <geometry>
                              <box>
                                    <size>.15 .05 .05</size>
                              </box>
                        </geometry>
                  </visual>
                  <collision name = 'left_mount_collision'>
                        <pose> 0.15 0 0 0 0 0 </pose>
                        <geometry>
                              <box>
                                    <size>.15 .05 .05</size>
                              </box>
                        </geometry>
                  </collision>
            </link>

            <link name = 'right_thrust'>
                  <!-- right thruster housing and mount block -->
                  <pose relative_to = 'body'> 0.3 0 .3 0 0 3.14 </pose>
                  <!-- pose> -0.3 0 0.3 0 0 2 </pose> -->
                  <inertial>
                        <mass>13.0</mass>
                        <!-- same source as body inertias -->
                        <inertia>
                              <ixx>0.083</ixx>
                              <ixy>0.0</ixy>
                              <ixz>0.0</ixz>
                              <iyy>0.083</iyy>
                              <iyz>0.0</iyz>
                              <izz>0.083</izz>
                        </inertia>
                  </inertial>

                  <visual name = 'right_housing_visual'>
                        <geometry>
                              <cylinder>
                                    <radius>0.05</radius>
                                    <length>0.3</length>
                              </cylinder>
                        </geometry>
                        <!--<pose> 0.15 0 0 0 0 0 </pose>-->
                  </visual>

                  <collision name='right_housing_collision'>
                        <geometry>
                              <cylinder>
                                    <radius>0.05</radius>
                                    <length>0.3</length>
                              </cylinder>
                        </geometry>
                  </collision>

                  <visual name = 'right_mount_visual'>
                        <pose> 0.1 0 0 0 0 0 </pose>
                        <geometry>
                              <box>
                                    <size>.15 .05 .05</size>
                              </box>
                        </geometry>
                  </visual>
                  <collision name = 'right_mount_collision'>
                        <pose> 0.15 0 0 0 0 0 </pose>
                        <geometry>
                              <box>
                                    <size>.15 .05 .05</size>
                              </box>
                        </geometry>
                  </collision>
            </link>

            <link name = 'left_prop'>
                  <pose relative_to = 'left_thrust'>  0 0 .16 0 0 0 </pose>
                  <inertial>
                        <mass>3.0</mass>
                        <!-- same source as body inertias -->
                        <inertia>
                              <ixx>0.083</ixx>
                              <ixy>0.0</ixy>
                              <ixz>0.0</ixz>
                              <iyy>0.083</iyy>
                              <iyz>0.0</iyz>
                              <izz>0.083</izz>
                        </inertia>
                  </inertial>

                  <visual name=Lblade1_visual>
                        <pose>.06 0 0 0.6 0 0</pose>
                        <geometry>
                              <box>
                                    <size>0.1 0.025 0.005</size>
                              </box>
                        </geometry>
                  </visual>
                  <collision name=Lblade1_collision>
                        <pose>.06 0 0 0.6 0 0</pose>
                        <geometry>
                              <box>
                                    <size>0.1 0.025 0.005</size>
                              </box>
                        </geometry>
                  </collision>

                  <visual name=Lblade2_visual>
                        <pose>-.06 0 0 -0.6 0 0</pose>
                        <geometry>
                              <box>
                                    <size>0.1 0.025 0.005</size>
                              </box>
                        </geometry>
                  </visual>
                  <collision name=Lblade2_collision>
                        <pose>-.06 0 0 -0.6 0 0</pose>
                        <geometry>
                              <box>
                                    <size>0.1 0.025 0.005</size>
                              </box>
                        </geometry>
                  </collision>
      </link>

      <link name = 'right_prop'>
            <pose relative_to = 'right_thrust'>  0 0 .16 0 0 0 </pose>
            <inertial>
                  <mass>3.0</mass>
                  <!-- same source as body inertias -->
                  <inertia>
                        <ixx>0.083</ixx>
                        <ixy>0.0</ixy>
                        <ixz>0.0</ixz>
                        <iyy>0.083</iyy>
                        <iyz>0.0</iyz>
                        <izz>0.083</izz>
                  </inertia>
            </inertial>

            <visual name=Rblade1_visual>
                  <pose>.06 0 0 0.6 0 0</pose>
                  <geometry>
                        <box>
                              <size>0.1 0.025 0.005</size>
                        </box>
                  </geometry>
            </visual>
            <collision name=Rblade1_collision>
                  <pose>.06 0 0 0.6 0 0</pose>
                  <geometry>
                        <box>
                              <size>0.1 0.025 0.005</size>
                        </box>
                  </geometry>
            </collision>

            <visual name=Rblade2_visual>
                  <pose>-.06 0 0 -0.6 0 0</pose>
                  <geometry>
                        <box>
                              <size>0.1 0.025 0.005</size>
                        </box>
                  </geometry>
            </visual>
            <collision name=Rblade2_collision>
                  <pose>-.06 0 0 -0.6 0 0</pose>
                  <geometry>
                        <box>
                              <size>0.1 0.025 0.005</size>
                        </box>
                  </geometry>
            </collision>
      </link>


            <!-- joints -->
            <joint name = "keel_joint" type = "fixed">
                  <parent> body </parent>
                  <child> keel </child>
                  <pose relative_to = 'body'> 0 -0.15 0.1 0 0 0 </pose>
            </joint>

            <joint name = "left_thrust_joint" type = "fixed">
                  <parent> body </parent>
                  <child> left_thrust </child>
                  <pose relative_to = 'left_thrust'> 0.1 0 0 0 0 0 </pose>
            </joint>

            <joint name = "right_thrust_joint" type = "fixed">
                  <parent> body </parent>
                  <child> right_thrust </child>
                  <pose relative_to = 'right_thrust'> 0.1 0 0 0 0 0 </pose>
            </joint>

            <joint name = 'left_hub_joint' type = 'revolute'>
                  <parent> left_thrust </parent>
                  <child> left_prop </child>
                  <pose relative_to = 'left_prop'> 0 0 -0.02 0 0 0 </pose>
                  <axis>
                        <xyz>0 0 1</xyz>
                        <use_parent_model_frame>true</use_parent_model_frame>
                  </axis>
            </joint>

            <joint name = 'right_hub_joint' type = 'revolute'>
                  <parent> right_thrust </parent>
                  <child> right_prop </child>
                  <pose relative_to = 'right_prop'> 0 0 -0.02 0 0 0 </pose>
                  <axis>
                        <xyz>0 0 1</xyz>
                        <use_parent_model_frame>true</use_parent_model_frame>
                  </axis>
            </joint>

            <plugin name="buoyancy" filename="libBuoyancyPlugin.so">
                  <fluid_density>999.1026</fluid_density>
            </plugin>
      </model>
</sdf>
